import React from 'react';
import Error from 'next/error';

import { captureException } from '../lib/sentry';

const MyError = ({ statusCode, hasGetInitialPropsRun, err }) => {
  if (!hasGetInitialPropsRun && err) {
    // getInitialProps is not called in case of
    // https://github.com/zeit/next.js/issues/8592. As a workaround, we pass
    // err via _app.js so it can be captured
    console.log('$$$$$ error at: getInitialProps is not called in case of');
    captureException(err);
  }

  return <Error statusCode={statusCode} />;
};

MyError.getInitialProps = async ctx => {
  const { res, err, asPath } = ctx;
  const errorInitialProps = await Error.getInitialProps({ res, err });

  // Workaround for https://github.com/zeit/next.js/issues/8592, mark when
  // getInitialProps has run
  errorInitialProps.hasGetInitialPropsRun = true;

  if (res) {
    // Running on the server, the response object is available.
    console.log(
      '$$$$$ do we have a response object? ',
      typeof res === 'object',
    );
    console.log('$$$$$ Status code', res.statusCode);
    console.log('$$$$$ asPath is: ', asPath);
    console.log('$$$$$ err is: ', err);

    // Next.js will pass an err on the server if a page's `getInitialProps`
    // threw or returned a Promise that rejected

    if (res.statusCode === 404) {
      // Opinionated: do not record an exception in Sentry for 404
      return { statusCode: 404 };
    }

    if (err) {
      captureException(err, ctx);
      return errorInitialProps;
    }
  } else if (err) {
    // Running on the client (browser).
    //
    // Next.js will provide an err if:
    //
    //  - a page's `getInitialProps` threw or returned a Promise that rejected
    //  - an exception was thrown somewhere in the React lifecycle (render,
    //    componentDidMount, etc) that was caught by Next.js's React Error
    //    Boundary. Read more about what types of exceptions are caught by Error
    //    Boundaries: https://reactjs.org/docs/error-boundaries.html

    console.log('$$$$$ we have an error object');

    captureException(err, ctx);
    return errorInitialProps;
  }

  // If this point is reached, getInitialProps was called without any
  // information about what the error might be. This is unexpected and may
  // indicate a bug introduced in Next.js, so record it in Sentry
  console.log('$$$$$ we ahve a conditions which shouldnt happen');
  captureException(
    new Error(`_error.js getInitialProps missing data at path: ${asPath}`),
    ctx,
  );

  return errorInitialProps;
};

export default MyError;
